Exception in thread Thread-1:
Traceback (most recent call last):
  File "/usr/lib/python3.10/threading.py", line 1016, in _bootstrap_inner
    self.run()
  File "/home/ubuntu/cc-bench/env/lib/python3.10/site-packages/redis/client.py", line 1788, in run
    pubsub.get_message(ignore_subscribe_messages=True, timeout=sleep_time)
  File "/home/ubuntu/cc-bench/env/lib/python3.10/site-packages/redis/client.py", line 1679, in get_message
    response = self.parse_response(block=(timeout is None), timeout=timeout)
  File "/home/ubuntu/cc-bench/env/lib/python3.10/site-packages/redis/client.py", line 1531, in parse_response
    response = self._execute(conn, try_read)
  File "/home/ubuntu/cc-bench/env/lib/python3.10/site-packages/redis/client.py", line 1507, in _execute
    return conn.retry.call_with_retry(
  File "/home/ubuntu/cc-bench/env/lib/python3.10/site-packages/redis/retry.py", line 49, in call_with_retry
    fail(error)
  File "/home/ubuntu/cc-bench/env/lib/python3.10/site-packages/redis/client.py", line 1509, in <lambda>
    lambda error: self._disconnect_raise_connect(conn, error),
  File "/home/ubuntu/cc-bench/env/lib/python3.10/site-packages/redis/client.py", line 1496, in _disconnect_raise_connect
    raise error
  File "/home/ubuntu/cc-bench/env/lib/python3.10/site-packages/redis/retry.py", line 46, in call_with_retry
    return do()
  File "/home/ubuntu/cc-bench/env/lib/python3.10/site-packages/redis/client.py", line 1508, in <lambda>
    lambda: command(*args, **kwargs),
  File "/home/ubuntu/cc-bench/env/lib/python3.10/site-packages/redis/client.py", line 1525, in try_read
    if not conn.can_read(timeout=timeout):
  File "/home/ubuntu/cc-bench/env/lib/python3.10/site-packages/redis/connection.py", line 854, in can_read
    return self._parser.can_read(timeout)
  File "/home/ubuntu/cc-bench/env/lib/python3.10/site-packages/redis/connection.py", line 443, in can_read
    return self.read_from_socket(timeout=timeout, raise_on_timeout=False)
  File "/home/ubuntu/cc-bench/env/lib/python3.10/site-packages/redis/connection.py", line 454, in read_from_socket
    raise ConnectionError(SERVER_CLOSED_CONNECTION_ERROR)
redis.exceptions.ConnectionError: Connection closed by server.
Traceback (most recent call last):
  File "/home/ubuntu/cc-bench/env/lib/python3.10/site-packages/redis/connection.py", line 698, in connect
    sock = self.retry.call_with_retry(
  File "/home/ubuntu/cc-bench/env/lib/python3.10/site-packages/redis/retry.py", line 46, in call_with_retry
    return do()
  File "/home/ubuntu/cc-bench/env/lib/python3.10/site-packages/redis/connection.py", line 699, in <lambda>
    lambda: self._connect(), lambda error: self.disconnect(error)
  File "/home/ubuntu/cc-bench/env/lib/python3.10/site-packages/redis/connection.py", line 987, in _connect
    raise err
  File "/home/ubuntu/cc-bench/env/lib/python3.10/site-packages/redis/connection.py", line 975, in _connect
    sock.connect(socket_address)
ConnectionRefusedError: [Errno 111] Connection refused

During handling of the above exception, another exception occurred:

Traceback (most recent call last):
  File "/usr/lib/python3.10/runpy.py", line 196, in _run_module_as_main
    return _run_code(code, main_globals, None,
  File "/usr/lib/python3.10/runpy.py", line 86, in _run_code
    exec(code, run_globals)
  File "/home/ubuntu/cc-bench/apps/frappe/frappe/utils/bench_helper.py", line 104, in <module>
    main()
  File "/home/ubuntu/cc-bench/apps/frappe/frappe/utils/bench_helper.py", line 19, in main
    click.Group(commands=commands)(prog_name="bench")
  File "/home/ubuntu/cc-bench/env/lib/python3.10/site-packages/click/core.py", line 1130, in __call__
    return self.main(*args, **kwargs)
  File "/home/ubuntu/cc-bench/env/lib/python3.10/site-packages/click/core.py", line 1055, in main
    rv = self.invoke(ctx)
  File "/home/ubuntu/cc-bench/env/lib/python3.10/site-packages/click/core.py", line 1657, in invoke
    return _process_result(sub_ctx.command.invoke(sub_ctx))
  File "/home/ubuntu/cc-bench/env/lib/python3.10/site-packages/click/core.py", line 1657, in invoke
    return _process_result(sub_ctx.command.invoke(sub_ctx))
  File "/home/ubuntu/cc-bench/env/lib/python3.10/site-packages/click/core.py", line 1404, in invoke
    return ctx.invoke(self.callback, **ctx.params)
  File "/home/ubuntu/cc-bench/env/lib/python3.10/site-packages/click/core.py", line 760, in invoke
    return __callback(*args, **kwargs)
  File "/home/ubuntu/cc-bench/apps/frappe/frappe/commands/scheduler.py", line 208, in start_worker
    start_worker(
  File "/home/ubuntu/cc-bench/apps/frappe/frappe/utils/background_jobs.py", line 249, in start_worker
    worker.work(
  File "/home/ubuntu/cc-bench/env/lib/python3.10/site-packages/rq/worker.py", line 645, in work
    self.unsubscribe()
  File "/home/ubuntu/cc-bench/env/lib/python3.10/site-packages/rq/worker.py", line 550, in unsubscribe
    self.pubsub.unsubscribe()
  File "/home/ubuntu/cc-bench/env/lib/python3.10/site-packages/redis/client.py", line 1648, in unsubscribe
    return self.execute_command("UNSUBSCRIBE", *args)
  File "/home/ubuntu/cc-bench/env/lib/python3.10/site-packages/redis/client.py", line 1468, in execute_command
    self._execute(connection, connection.send_command, *args, **kwargs)
  File "/home/ubuntu/cc-bench/env/lib/python3.10/site-packages/redis/client.py", line 1507, in _execute
    return conn.retry.call_with_retry(
  File "/home/ubuntu/cc-bench/env/lib/python3.10/site-packages/redis/retry.py", line 49, in call_with_retry
    fail(error)
  File "/home/ubuntu/cc-bench/env/lib/python3.10/site-packages/redis/client.py", line 1509, in <lambda>
    lambda error: self._disconnect_raise_connect(conn, error),
  File "/home/ubuntu/cc-bench/env/lib/python3.10/site-packages/redis/client.py", line 1496, in _disconnect_raise_connect
    raise error
  File "/home/ubuntu/cc-bench/env/lib/python3.10/site-packages/redis/retry.py", line 46, in call_with_retry
    return do()
  File "/home/ubuntu/cc-bench/env/lib/python3.10/site-packages/redis/client.py", line 1508, in <lambda>
    lambda: command(*args, **kwargs),
  File "/home/ubuntu/cc-bench/env/lib/python3.10/site-packages/redis/connection.py", line 840, in send_command
    self.send_packed_command(
  File "/home/ubuntu/cc-bench/env/lib/python3.10/site-packages/redis/connection.py", line 814, in send_packed_command
    self.connect()
  File "/home/ubuntu/cc-bench/env/lib/python3.10/site-packages/redis/connection.py", line 704, in connect
    raise ConnectionError(self._error_message(e))
redis.exceptions.ConnectionError: Error 111 connecting to localhost:11000. Connection refused.
Exception in thread Thread-1:
Traceback (most recent call last):
  File "/usr/lib/python3.10/threading.py", line 1016, in _bootstrap_inner
    self.run()
  File "/home/ubuntu/cc-bench/env/lib/python3.10/site-packages/redis/client.py", line 1788, in run
    pubsub.get_message(ignore_subscribe_messages=True, timeout=sleep_time)
  File "/home/ubuntu/cc-bench/env/lib/python3.10/site-packages/redis/client.py", line 1679, in get_message
    response = self.parse_response(block=(timeout is None), timeout=timeout)
  File "/home/ubuntu/cc-bench/env/lib/python3.10/site-packages/redis/client.py", line 1531, in parse_response
    response = self._execute(conn, try_read)
  File "/home/ubuntu/cc-bench/env/lib/python3.10/site-packages/redis/client.py", line 1507, in _execute
    return conn.retry.call_with_retry(
  File "/home/ubuntu/cc-bench/env/lib/python3.10/site-packages/redis/retry.py", line 49, in call_with_retry
    fail(error)
  File "/home/ubuntu/cc-bench/env/lib/python3.10/site-packages/redis/client.py", line 1509, in <lambda>
    lambda error: self._disconnect_raise_connect(conn, error),
  File "/home/ubuntu/cc-bench/env/lib/python3.10/site-packages/redis/client.py", line 1496, in _disconnect_raise_connect
    raise error
  File "/home/ubuntu/cc-bench/env/lib/python3.10/site-packages/redis/retry.py", line 46, in call_with_retry
    return do()
  File "/home/ubuntu/cc-bench/env/lib/python3.10/site-packages/redis/client.py", line 1508, in <lambda>
    lambda: command(*args, **kwargs),
  File "/home/ubuntu/cc-bench/env/lib/python3.10/site-packages/redis/client.py", line 1525, in try_read
    if not conn.can_read(timeout=timeout):
  File "/home/ubuntu/cc-bench/env/lib/python3.10/site-packages/redis/connection.py", line 854, in can_read
    return self._parser.can_read(timeout)
  File "/home/ubuntu/cc-bench/env/lib/python3.10/site-packages/redis/connection.py", line 443, in can_read
    return self.read_from_socket(timeout=timeout, raise_on_timeout=False)
  File "/home/ubuntu/cc-bench/env/lib/python3.10/site-packages/redis/connection.py", line 454, in read_from_socket
    raise ConnectionError(SERVER_CLOSED_CONNECTION_ERROR)
redis.exceptions.ConnectionError: Connection closed by server.
Traceback (most recent call last):
  File "/home/ubuntu/cc-bench/env/lib/python3.10/site-packages/redis/connection.py", line 698, in connect
    sock = self.retry.call_with_retry(
  File "/home/ubuntu/cc-bench/env/lib/python3.10/site-packages/redis/retry.py", line 46, in call_with_retry
    return do()
  File "/home/ubuntu/cc-bench/env/lib/python3.10/site-packages/redis/connection.py", line 699, in <lambda>
    lambda: self._connect(), lambda error: self.disconnect(error)
  File "/home/ubuntu/cc-bench/env/lib/python3.10/site-packages/redis/connection.py", line 987, in _connect
    raise err
  File "/home/ubuntu/cc-bench/env/lib/python3.10/site-packages/redis/connection.py", line 975, in _connect
    sock.connect(socket_address)
ConnectionRefusedError: [Errno 111] Connection refused

During handling of the above exception, another exception occurred:

Traceback (most recent call last):
  File "/usr/lib/python3.10/runpy.py", line 196, in _run_module_as_main
    return _run_code(code, main_globals, None,
  File "/usr/lib/python3.10/runpy.py", line 86, in _run_code
    exec(code, run_globals)
  File "/home/ubuntu/cc-bench/apps/frappe/frappe/utils/bench_helper.py", line 104, in <module>
    main()
  File "/home/ubuntu/cc-bench/apps/frappe/frappe/utils/bench_helper.py", line 19, in main
    click.Group(commands=commands)(prog_name="bench")
  File "/home/ubuntu/cc-bench/env/lib/python3.10/site-packages/click/core.py", line 1130, in __call__
    return self.main(*args, **kwargs)
  File "/home/ubuntu/cc-bench/env/lib/python3.10/site-packages/click/core.py", line 1055, in main
    rv = self.invoke(ctx)
  File "/home/ubuntu/cc-bench/env/lib/python3.10/site-packages/click/core.py", line 1657, in invoke
    return _process_result(sub_ctx.command.invoke(sub_ctx))
  File "/home/ubuntu/cc-bench/env/lib/python3.10/site-packages/click/core.py", line 1657, in invoke
    return _process_result(sub_ctx.command.invoke(sub_ctx))
  File "/home/ubuntu/cc-bench/env/lib/python3.10/site-packages/click/core.py", line 1404, in invoke
    return ctx.invoke(self.callback, **ctx.params)
  File "/home/ubuntu/cc-bench/env/lib/python3.10/site-packages/click/core.py", line 760, in invoke
    return __callback(*args, **kwargs)
  File "/home/ubuntu/cc-bench/apps/frappe/frappe/commands/scheduler.py", line 208, in start_worker
    start_worker(
  File "/home/ubuntu/cc-bench/apps/frappe/frappe/utils/background_jobs.py", line 249, in start_worker
    worker.work(
  File "/home/ubuntu/cc-bench/env/lib/python3.10/site-packages/rq/worker.py", line 645, in work
    self.unsubscribe()
  File "/home/ubuntu/cc-bench/env/lib/python3.10/site-packages/rq/worker.py", line 550, in unsubscribe
    self.pubsub.unsubscribe()
  File "/home/ubuntu/cc-bench/env/lib/python3.10/site-packages/redis/client.py", line 1648, in unsubscribe
    return self.execute_command("UNSUBSCRIBE", *args)
  File "/home/ubuntu/cc-bench/env/lib/python3.10/site-packages/redis/client.py", line 1468, in execute_command
    self._execute(connection, connection.send_command, *args, **kwargs)
  File "/home/ubuntu/cc-bench/env/lib/python3.10/site-packages/redis/client.py", line 1507, in _execute
    return conn.retry.call_with_retry(
  File "/home/ubuntu/cc-bench/env/lib/python3.10/site-packages/redis/retry.py", line 49, in call_with_retry
    fail(error)
  File "/home/ubuntu/cc-bench/env/lib/python3.10/site-packages/redis/client.py", line 1509, in <lambda>
    lambda error: self._disconnect_raise_connect(conn, error),
  File "/home/ubuntu/cc-bench/env/lib/python3.10/site-packages/redis/client.py", line 1496, in _disconnect_raise_connect
    raise error
  File "/home/ubuntu/cc-bench/env/lib/python3.10/site-packages/redis/retry.py", line 46, in call_with_retry
    return do()
  File "/home/ubuntu/cc-bench/env/lib/python3.10/site-packages/redis/client.py", line 1508, in <lambda>
    lambda: command(*args, **kwargs),
  File "/home/ubuntu/cc-bench/env/lib/python3.10/site-packages/redis/connection.py", line 840, in send_command
    self.send_packed_command(
  File "/home/ubuntu/cc-bench/env/lib/python3.10/site-packages/redis/connection.py", line 814, in send_packed_command
    self.connect()
  File "/home/ubuntu/cc-bench/env/lib/python3.10/site-packages/redis/connection.py", line 704, in connect
    raise ConnectionError(self._error_message(e))
redis.exceptions.ConnectionError: Error 111 connecting to localhost:11000. Connection refused.
Exception in thread Thread-1:
Traceback (most recent call last):
  File "/usr/lib/python3.10/threading.py", line 1016, in _bootstrap_inner
    self.run()
  File "/home/ubuntu/cc-bench/env/lib/python3.10/site-packages/redis/client.py", line 1788, in run
    pubsub.get_message(ignore_subscribe_messages=True, timeout=sleep_time)
  File "/home/ubuntu/cc-bench/env/lib/python3.10/site-packages/redis/client.py", line 1679, in get_message
    response = self.parse_response(block=(timeout is None), timeout=timeout)
  File "/home/ubuntu/cc-bench/env/lib/python3.10/site-packages/redis/client.py", line 1531, in parse_response
    response = self._execute(conn, try_read)
  File "/home/ubuntu/cc-bench/env/lib/python3.10/site-packages/redis/client.py", line 1507, in _execute
    return conn.retry.call_with_retry(
  File "/home/ubuntu/cc-bench/env/lib/python3.10/site-packages/redis/retry.py", line 49, in call_with_retry
    fail(error)
  File "/home/ubuntu/cc-bench/env/lib/python3.10/site-packages/redis/client.py", line 1509, in <lambda>
    lambda error: self._disconnect_raise_connect(conn, error),
  File "/home/ubuntu/cc-bench/env/lib/python3.10/site-packages/redis/client.py", line 1496, in _disconnect_raise_connect
    raise error
  File "/home/ubuntu/cc-bench/env/lib/python3.10/site-packages/redis/retry.py", line 46, in call_with_retry
    return do()
  File "/home/ubuntu/cc-bench/env/lib/python3.10/site-packages/redis/client.py", line 1508, in <lambda>
    lambda: command(*args, **kwargs),
  File "/home/ubuntu/cc-bench/env/lib/python3.10/site-packages/redis/client.py", line 1525, in try_read
    if not conn.can_read(timeout=timeout):
  File "/home/ubuntu/cc-bench/env/lib/python3.10/site-packages/redis/connection.py", line 854, in can_read
    return self._parser.can_read(timeout)
  File "/home/ubuntu/cc-bench/env/lib/python3.10/site-packages/redis/connection.py", line 443, in can_read
    return self.read_from_socket(timeout=timeout, raise_on_timeout=False)
  File "/home/ubuntu/cc-bench/env/lib/python3.10/site-packages/redis/connection.py", line 454, in read_from_socket
    raise ConnectionError(SERVER_CLOSED_CONNECTION_ERROR)
redis.exceptions.ConnectionError: Connection closed by server.
Traceback (most recent call last):
  File "/home/ubuntu/cc-bench/env/lib/python3.10/site-packages/redis/connection.py", line 698, in connect
    sock = self.retry.call_with_retry(
  File "/home/ubuntu/cc-bench/env/lib/python3.10/site-packages/redis/retry.py", line 46, in call_with_retry
    return do()
  File "/home/ubuntu/cc-bench/env/lib/python3.10/site-packages/redis/connection.py", line 699, in <lambda>
    lambda: self._connect(), lambda error: self.disconnect(error)
  File "/home/ubuntu/cc-bench/env/lib/python3.10/site-packages/redis/connection.py", line 987, in _connect
    raise err
  File "/home/ubuntu/cc-bench/env/lib/python3.10/site-packages/redis/connection.py", line 975, in _connect
    sock.connect(socket_address)
ConnectionRefusedError: [Errno 111] Connection refused

During handling of the above exception, another exception occurred:

Traceback (most recent call last):
  File "/usr/lib/python3.10/runpy.py", line 196, in _run_module_as_main
    return _run_code(code, main_globals, None,
  File "/usr/lib/python3.10/runpy.py", line 86, in _run_code
    exec(code, run_globals)
  File "/home/ubuntu/cc-bench/apps/frappe/frappe/utils/bench_helper.py", line 104, in <module>
    main()
  File "/home/ubuntu/cc-bench/apps/frappe/frappe/utils/bench_helper.py", line 19, in main
    click.Group(commands=commands)(prog_name="bench")
  File "/home/ubuntu/cc-bench/env/lib/python3.10/site-packages/click/core.py", line 1130, in __call__
    return self.main(*args, **kwargs)
  File "/home/ubuntu/cc-bench/env/lib/python3.10/site-packages/click/core.py", line 1055, in main
    rv = self.invoke(ctx)
  File "/home/ubuntu/cc-bench/env/lib/python3.10/site-packages/click/core.py", line 1657, in invoke
    return _process_result(sub_ctx.command.invoke(sub_ctx))
  File "/home/ubuntu/cc-bench/env/lib/python3.10/site-packages/click/core.py", line 1657, in invoke
    return _process_result(sub_ctx.command.invoke(sub_ctx))
  File "/home/ubuntu/cc-bench/env/lib/python3.10/site-packages/click/core.py", line 1404, in invoke
    return ctx.invoke(self.callback, **ctx.params)
  File "/home/ubuntu/cc-bench/env/lib/python3.10/site-packages/click/core.py", line 760, in invoke
    return __callback(*args, **kwargs)
  File "/home/ubuntu/cc-bench/apps/frappe/frappe/commands/scheduler.py", line 208, in start_worker
    start_worker(
  File "/home/ubuntu/cc-bench/apps/frappe/frappe/utils/background_jobs.py", line 249, in start_worker
    worker.work(
  File "/home/ubuntu/cc-bench/env/lib/python3.10/site-packages/rq/worker.py", line 645, in work
    self.unsubscribe()
  File "/home/ubuntu/cc-bench/env/lib/python3.10/site-packages/rq/worker.py", line 550, in unsubscribe
    self.pubsub.unsubscribe()
  File "/home/ubuntu/cc-bench/env/lib/python3.10/site-packages/redis/client.py", line 1648, in unsubscribe
    return self.execute_command("UNSUBSCRIBE", *args)
  File "/home/ubuntu/cc-bench/env/lib/python3.10/site-packages/redis/client.py", line 1468, in execute_command
    self._execute(connection, connection.send_command, *args, **kwargs)
  File "/home/ubuntu/cc-bench/env/lib/python3.10/site-packages/redis/client.py", line 1507, in _execute
    return conn.retry.call_with_retry(
  File "/home/ubuntu/cc-bench/env/lib/python3.10/site-packages/redis/retry.py", line 49, in call_with_retry
    fail(error)
  File "/home/ubuntu/cc-bench/env/lib/python3.10/site-packages/redis/client.py", line 1509, in <lambda>
    lambda error: self._disconnect_raise_connect(conn, error),
  File "/home/ubuntu/cc-bench/env/lib/python3.10/site-packages/redis/client.py", line 1496, in _disconnect_raise_connect
    raise error
  File "/home/ubuntu/cc-bench/env/lib/python3.10/site-packages/redis/retry.py", line 46, in call_with_retry
    return do()
  File "/home/ubuntu/cc-bench/env/lib/python3.10/site-packages/redis/client.py", line 1508, in <lambda>
    lambda: command(*args, **kwargs),
  File "/home/ubuntu/cc-bench/env/lib/python3.10/site-packages/redis/connection.py", line 840, in send_command
    self.send_packed_command(
  File "/home/ubuntu/cc-bench/env/lib/python3.10/site-packages/redis/connection.py", line 814, in send_packed_command
    self.connect()
  File "/home/ubuntu/cc-bench/env/lib/python3.10/site-packages/redis/connection.py", line 704, in connect
    raise ConnectionError(self._error_message(e))
redis.exceptions.ConnectionError: Error 111 connecting to localhost:11000. Connection refused.
Exception in thread Thread-1:
Traceback (most recent call last):
  File "/usr/lib/python3.10/threading.py", line 1016, in _bootstrap_inner
    self.run()
  File "/home/ubuntu/cc-bench/env/lib/python3.10/site-packages/redis/client.py", line 1788, in run
    pubsub.get_message(ignore_subscribe_messages=True, timeout=sleep_time)
  File "/home/ubuntu/cc-bench/env/lib/python3.10/site-packages/redis/client.py", line 1679, in get_message
    response = self.parse_response(block=(timeout is None), timeout=timeout)
  File "/home/ubuntu/cc-bench/env/lib/python3.10/site-packages/redis/client.py", line 1531, in parse_response
    response = self._execute(conn, try_read)
  File "/home/ubuntu/cc-bench/env/lib/python3.10/site-packages/redis/client.py", line 1507, in _execute
    return conn.retry.call_with_retry(
  File "/home/ubuntu/cc-bench/env/lib/python3.10/site-packages/redis/retry.py", line 49, in call_with_retry
    fail(error)
  File "/home/ubuntu/cc-bench/env/lib/python3.10/site-packages/redis/client.py", line 1509, in <lambda>
    lambda error: self._disconnect_raise_connect(conn, error),
  File "/home/ubuntu/cc-bench/env/lib/python3.10/site-packages/redis/client.py", line 1496, in _disconnect_raise_connect
    raise error
  File "/home/ubuntu/cc-bench/env/lib/python3.10/site-packages/redis/retry.py", line 46, in call_with_retry
    return do()
  File "/home/ubuntu/cc-bench/env/lib/python3.10/site-packages/redis/client.py", line 1508, in <lambda>
    lambda: command(*args, **kwargs),
  File "/home/ubuntu/cc-bench/env/lib/python3.10/site-packages/redis/client.py", line 1525, in try_read
    if not conn.can_read(timeout=timeout):
  File "/home/ubuntu/cc-bench/env/lib/python3.10/site-packages/redis/connection.py", line 854, in can_read
    return self._parser.can_read(timeout)
  File "/home/ubuntu/cc-bench/env/lib/python3.10/site-packages/redis/connection.py", line 443, in can_read
    return self.read_from_socket(timeout=timeout, raise_on_timeout=False)
  File "/home/ubuntu/cc-bench/env/lib/python3.10/site-packages/redis/connection.py", line 454, in read_from_socket
    raise ConnectionError(SERVER_CLOSED_CONNECTION_ERROR)
redis.exceptions.ConnectionError: Connection closed by server.
Traceback (most recent call last):
  File "/home/ubuntu/cc-bench/env/lib/python3.10/site-packages/redis/connection.py", line 698, in connect
    sock = self.retry.call_with_retry(
  File "/home/ubuntu/cc-bench/env/lib/python3.10/site-packages/redis/retry.py", line 46, in call_with_retry
    return do()
  File "/home/ubuntu/cc-bench/env/lib/python3.10/site-packages/redis/connection.py", line 699, in <lambda>
    lambda: self._connect(), lambda error: self.disconnect(error)
  File "/home/ubuntu/cc-bench/env/lib/python3.10/site-packages/redis/connection.py", line 987, in _connect
    raise err
  File "/home/ubuntu/cc-bench/env/lib/python3.10/site-packages/redis/connection.py", line 975, in _connect
    sock.connect(socket_address)
ConnectionRefusedError: [Errno 111] Connection refused

During handling of the above exception, another exception occurred:

Traceback (most recent call last):
  File "/usr/lib/python3.10/runpy.py", line 196, in _run_module_as_main
    return _run_code(code, main_globals, None,
  File "/usr/lib/python3.10/runpy.py", line 86, in _run_code
    exec(code, run_globals)
  File "/home/ubuntu/cc-bench/apps/frappe/frappe/utils/bench_helper.py", line 104, in <module>
    main()
  File "/home/ubuntu/cc-bench/apps/frappe/frappe/utils/bench_helper.py", line 19, in main
    click.Group(commands=commands)(prog_name="bench")
  File "/home/ubuntu/cc-bench/env/lib/python3.10/site-packages/click/core.py", line 1130, in __call__
    return self.main(*args, **kwargs)
  File "/home/ubuntu/cc-bench/env/lib/python3.10/site-packages/click/core.py", line 1055, in main
    rv = self.invoke(ctx)
  File "/home/ubuntu/cc-bench/env/lib/python3.10/site-packages/click/core.py", line 1657, in invoke
    return _process_result(sub_ctx.command.invoke(sub_ctx))
  File "/home/ubuntu/cc-bench/env/lib/python3.10/site-packages/click/core.py", line 1657, in invoke
    return _process_result(sub_ctx.command.invoke(sub_ctx))
  File "/home/ubuntu/cc-bench/env/lib/python3.10/site-packages/click/core.py", line 1404, in invoke
    return ctx.invoke(self.callback, **ctx.params)
  File "/home/ubuntu/cc-bench/env/lib/python3.10/site-packages/click/core.py", line 760, in invoke
    return __callback(*args, **kwargs)
  File "/home/ubuntu/cc-bench/apps/frappe/frappe/commands/scheduler.py", line 208, in start_worker
    start_worker(
  File "/home/ubuntu/cc-bench/apps/frappe/frappe/utils/background_jobs.py", line 249, in start_worker
    worker.work(
  File "/home/ubuntu/cc-bench/env/lib/python3.10/site-packages/rq/worker.py", line 645, in work
    self.unsubscribe()
  File "/home/ubuntu/cc-bench/env/lib/python3.10/site-packages/rq/worker.py", line 550, in unsubscribe
    self.pubsub.unsubscribe()
  File "/home/ubuntu/cc-bench/env/lib/python3.10/site-packages/redis/client.py", line 1648, in unsubscribe
    return self.execute_command("UNSUBSCRIBE", *args)
  File "/home/ubuntu/cc-bench/env/lib/python3.10/site-packages/redis/client.py", line 1468, in execute_command
    self._execute(connection, connection.send_command, *args, **kwargs)
  File "/home/ubuntu/cc-bench/env/lib/python3.10/site-packages/redis/client.py", line 1507, in _execute
    return conn.retry.call_with_retry(
  File "/home/ubuntu/cc-bench/env/lib/python3.10/site-packages/redis/retry.py", line 49, in call_with_retry
    fail(error)
  File "/home/ubuntu/cc-bench/env/lib/python3.10/site-packages/redis/client.py", line 1509, in <lambda>
    lambda error: self._disconnect_raise_connect(conn, error),
  File "/home/ubuntu/cc-bench/env/lib/python3.10/site-packages/redis/client.py", line 1496, in _disconnect_raise_connect
    raise error
  File "/home/ubuntu/cc-bench/env/lib/python3.10/site-packages/redis/retry.py", line 46, in call_with_retry
    return do()
  File "/home/ubuntu/cc-bench/env/lib/python3.10/site-packages/redis/client.py", line 1508, in <lambda>
    lambda: command(*args, **kwargs),
  File "/home/ubuntu/cc-bench/env/lib/python3.10/site-packages/redis/connection.py", line 840, in send_command
    self.send_packed_command(
  File "/home/ubuntu/cc-bench/env/lib/python3.10/site-packages/redis/connection.py", line 814, in send_packed_command
    self.connect()
  File "/home/ubuntu/cc-bench/env/lib/python3.10/site-packages/redis/connection.py", line 704, in connect
    raise ConnectionError(self._error_message(e))
redis.exceptions.ConnectionError: Error 111 connecting to localhost:11000. Connection refused.
Exception in thread Thread-1:
Traceback (most recent call last):
  File "/usr/lib/python3.10/threading.py", line 1016, in _bootstrap_inner
    self.run()
  File "/home/ubuntu/cc-bench/env/lib/python3.10/site-packages/redis/client.py", line 1788, in run
    pubsub.get_message(ignore_subscribe_messages=True, timeout=sleep_time)
  File "/home/ubuntu/cc-bench/env/lib/python3.10/site-packages/redis/client.py", line 1679, in get_message
    response = self.parse_response(block=(timeout is None), timeout=timeout)
  File "/home/ubuntu/cc-bench/env/lib/python3.10/site-packages/redis/client.py", line 1531, in parse_response
    response = self._execute(conn, try_read)
  File "/home/ubuntu/cc-bench/env/lib/python3.10/site-packages/redis/client.py", line 1507, in _execute
    return conn.retry.call_with_retry(
  File "/home/ubuntu/cc-bench/env/lib/python3.10/site-packages/redis/retry.py", line 49, in call_with_retry
    fail(error)
  File "/home/ubuntu/cc-bench/env/lib/python3.10/site-packages/redis/client.py", line 1509, in <lambda>
    lambda error: self._disconnect_raise_connect(conn, error),
  File "/home/ubuntu/cc-bench/env/lib/python3.10/site-packages/redis/client.py", line 1496, in _disconnect_raise_connect
    raise error
  File "/home/ubuntu/cc-bench/env/lib/python3.10/site-packages/redis/retry.py", line 46, in call_with_retry
    return do()
  File "/home/ubuntu/cc-bench/env/lib/python3.10/site-packages/redis/client.py", line 1508, in <lambda>
    lambda: command(*args, **kwargs),
  File "/home/ubuntu/cc-bench/env/lib/python3.10/site-packages/redis/client.py", line 1525, in try_read
    if not conn.can_read(timeout=timeout):
  File "/home/ubuntu/cc-bench/env/lib/python3.10/site-packages/redis/connection.py", line 854, in can_read
    return self._parser.can_read(timeout)
  File "/home/ubuntu/cc-bench/env/lib/python3.10/site-packages/redis/connection.py", line 443, in can_read
    return self.read_from_socket(timeout=timeout, raise_on_timeout=False)
  File "/home/ubuntu/cc-bench/env/lib/python3.10/site-packages/redis/connection.py", line 454, in read_from_socket
    raise ConnectionError(SERVER_CLOSED_CONNECTION_ERROR)
redis.exceptions.ConnectionError: Connection closed by server.
Traceback (most recent call last):
  File "/home/ubuntu/cc-bench/env/lib/python3.10/site-packages/redis/connection.py", line 698, in connect
    sock = self.retry.call_with_retry(
  File "/home/ubuntu/cc-bench/env/lib/python3.10/site-packages/redis/retry.py", line 46, in call_with_retry
    return do()
  File "/home/ubuntu/cc-bench/env/lib/python3.10/site-packages/redis/connection.py", line 699, in <lambda>
    lambda: self._connect(), lambda error: self.disconnect(error)
  File "/home/ubuntu/cc-bench/env/lib/python3.10/site-packages/redis/connection.py", line 987, in _connect
    raise err
  File "/home/ubuntu/cc-bench/env/lib/python3.10/site-packages/redis/connection.py", line 975, in _connect
    sock.connect(socket_address)
ConnectionRefusedError: [Errno 111] Connection refused

During handling of the above exception, another exception occurred:

Traceback (most recent call last):
  File "/usr/lib/python3.10/runpy.py", line 196, in _run_module_as_main
    return _run_code(code, main_globals, None,
  File "/usr/lib/python3.10/runpy.py", line 86, in _run_code
    exec(code, run_globals)
  File "/home/ubuntu/cc-bench/apps/frappe/frappe/utils/bench_helper.py", line 104, in <module>
    main()
  File "/home/ubuntu/cc-bench/apps/frappe/frappe/utils/bench_helper.py", line 19, in main
    click.Group(commands=commands)(prog_name="bench")
  File "/home/ubuntu/cc-bench/env/lib/python3.10/site-packages/click/core.py", line 1130, in __call__
    return self.main(*args, **kwargs)
  File "/home/ubuntu/cc-bench/env/lib/python3.10/site-packages/click/core.py", line 1055, in main
    rv = self.invoke(ctx)
  File "/home/ubuntu/cc-bench/env/lib/python3.10/site-packages/click/core.py", line 1657, in invoke
    return _process_result(sub_ctx.command.invoke(sub_ctx))
  File "/home/ubuntu/cc-bench/env/lib/python3.10/site-packages/click/core.py", line 1657, in invoke
    return _process_result(sub_ctx.command.invoke(sub_ctx))
  File "/home/ubuntu/cc-bench/env/lib/python3.10/site-packages/click/core.py", line 1404, in invoke
    return ctx.invoke(self.callback, **ctx.params)
  File "/home/ubuntu/cc-bench/env/lib/python3.10/site-packages/click/core.py", line 760, in invoke
    return __callback(*args, **kwargs)
  File "/home/ubuntu/cc-bench/apps/frappe/frappe/commands/scheduler.py", line 208, in start_worker
    start_worker(
  File "/home/ubuntu/cc-bench/apps/frappe/frappe/utils/background_jobs.py", line 249, in start_worker
    worker.work(
  File "/home/ubuntu/cc-bench/env/lib/python3.10/site-packages/rq/worker.py", line 645, in work
    self.unsubscribe()
  File "/home/ubuntu/cc-bench/env/lib/python3.10/site-packages/rq/worker.py", line 550, in unsubscribe
    self.pubsub.unsubscribe()
  File "/home/ubuntu/cc-bench/env/lib/python3.10/site-packages/redis/client.py", line 1648, in unsubscribe
    return self.execute_command("UNSUBSCRIBE", *args)
  File "/home/ubuntu/cc-bench/env/lib/python3.10/site-packages/redis/client.py", line 1468, in execute_command
    self._execute(connection, connection.send_command, *args, **kwargs)
  File "/home/ubuntu/cc-bench/env/lib/python3.10/site-packages/redis/client.py", line 1507, in _execute
    return conn.retry.call_with_retry(
  File "/home/ubuntu/cc-bench/env/lib/python3.10/site-packages/redis/retry.py", line 49, in call_with_retry
    fail(error)
  File "/home/ubuntu/cc-bench/env/lib/python3.10/site-packages/redis/client.py", line 1509, in <lambda>
    lambda error: self._disconnect_raise_connect(conn, error),
  File "/home/ubuntu/cc-bench/env/lib/python3.10/site-packages/redis/client.py", line 1496, in _disconnect_raise_connect
    raise error
  File "/home/ubuntu/cc-bench/env/lib/python3.10/site-packages/redis/retry.py", line 46, in call_with_retry
    return do()
  File "/home/ubuntu/cc-bench/env/lib/python3.10/site-packages/redis/client.py", line 1508, in <lambda>
    lambda: command(*args, **kwargs),
  File "/home/ubuntu/cc-bench/env/lib/python3.10/site-packages/redis/connection.py", line 840, in send_command
    self.send_packed_command(
  File "/home/ubuntu/cc-bench/env/lib/python3.10/site-packages/redis/connection.py", line 814, in send_packed_command
    self.connect()
  File "/home/ubuntu/cc-bench/env/lib/python3.10/site-packages/redis/connection.py", line 704, in connect
    raise ConnectionError(self._error_message(e))
redis.exceptions.ConnectionError: Error 111 connecting to localhost:11000. Connection refused.
Exception in thread Thread-1:
Traceback (most recent call last):
  File "/usr/lib/python3.10/threading.py", line 1016, in _bootstrap_inner
    self.run()
  File "/home/ubuntu/cc-bench/env/lib/python3.10/site-packages/redis/client.py", line 1788, in run
    pubsub.get_message(ignore_subscribe_messages=True, timeout=sleep_time)
  File "/home/ubuntu/cc-bench/env/lib/python3.10/site-packages/redis/client.py", line 1679, in get_message
    response = self.parse_response(block=(timeout is None), timeout=timeout)
  File "/home/ubuntu/cc-bench/env/lib/python3.10/site-packages/redis/client.py", line 1531, in parse_response
    response = self._execute(conn, try_read)
  File "/home/ubuntu/cc-bench/env/lib/python3.10/site-packages/redis/client.py", line 1507, in _execute
    return conn.retry.call_with_retry(
  File "/home/ubuntu/cc-bench/env/lib/python3.10/site-packages/redis/retry.py", line 49, in call_with_retry
    fail(error)
  File "/home/ubuntu/cc-bench/env/lib/python3.10/site-packages/redis/client.py", line 1509, in <lambda>
    lambda error: self._disconnect_raise_connect(conn, error),
  File "/home/ubuntu/cc-bench/env/lib/python3.10/site-packages/redis/client.py", line 1496, in _disconnect_raise_connect
    raise error
  File "/home/ubuntu/cc-bench/env/lib/python3.10/site-packages/redis/retry.py", line 46, in call_with_retry
    return do()
  File "/home/ubuntu/cc-bench/env/lib/python3.10/site-packages/redis/client.py", line 1508, in <lambda>
    lambda: command(*args, **kwargs),
  File "/home/ubuntu/cc-bench/env/lib/python3.10/site-packages/redis/client.py", line 1525, in try_read
    if not conn.can_read(timeout=timeout):
  File "/home/ubuntu/cc-bench/env/lib/python3.10/site-packages/redis/connection.py", line 854, in can_read
    return self._parser.can_read(timeout)
  File "/home/ubuntu/cc-bench/env/lib/python3.10/site-packages/redis/connection.py", line 443, in can_read
    return self.read_from_socket(timeout=timeout, raise_on_timeout=False)
  File "/home/ubuntu/cc-bench/env/lib/python3.10/site-packages/redis/connection.py", line 454, in read_from_socket
    raise ConnectionError(SERVER_CLOSED_CONNECTION_ERROR)
redis.exceptions.ConnectionError: Connection closed by server.
Traceback (most recent call last):
  File "/home/ubuntu/cc-bench/env/lib/python3.10/site-packages/redis/connection.py", line 698, in connect
    sock = self.retry.call_with_retry(
  File "/home/ubuntu/cc-bench/env/lib/python3.10/site-packages/redis/retry.py", line 46, in call_with_retry
    return do()
  File "/home/ubuntu/cc-bench/env/lib/python3.10/site-packages/redis/connection.py", line 699, in <lambda>
    lambda: self._connect(), lambda error: self.disconnect(error)
  File "/home/ubuntu/cc-bench/env/lib/python3.10/site-packages/redis/connection.py", line 987, in _connect
    raise err
  File "/home/ubuntu/cc-bench/env/lib/python3.10/site-packages/redis/connection.py", line 975, in _connect
    sock.connect(socket_address)
ConnectionRefusedError: [Errno 111] Connection refused

During handling of the above exception, another exception occurred:

Traceback (most recent call last):
  File "/usr/lib/python3.10/runpy.py", line 196, in _run_module_as_main
    return _run_code(code, main_globals, None,
  File "/usr/lib/python3.10/runpy.py", line 86, in _run_code
    exec(code, run_globals)
  File "/home/ubuntu/cc-bench/apps/frappe/frappe/utils/bench_helper.py", line 104, in <module>
    main()
  File "/home/ubuntu/cc-bench/apps/frappe/frappe/utils/bench_helper.py", line 19, in main
    click.Group(commands=commands)(prog_name="bench")
  File "/home/ubuntu/cc-bench/env/lib/python3.10/site-packages/click/core.py", line 1130, in __call__
    return self.main(*args, **kwargs)
  File "/home/ubuntu/cc-bench/env/lib/python3.10/site-packages/click/core.py", line 1055, in main
    rv = self.invoke(ctx)
  File "/home/ubuntu/cc-bench/env/lib/python3.10/site-packages/click/core.py", line 1657, in invoke
    return _process_result(sub_ctx.command.invoke(sub_ctx))
  File "/home/ubuntu/cc-bench/env/lib/python3.10/site-packages/click/core.py", line 1657, in invoke
    return _process_result(sub_ctx.command.invoke(sub_ctx))
  File "/home/ubuntu/cc-bench/env/lib/python3.10/site-packages/click/core.py", line 1404, in invoke
    return ctx.invoke(self.callback, **ctx.params)
  File "/home/ubuntu/cc-bench/env/lib/python3.10/site-packages/click/core.py", line 760, in invoke
    return __callback(*args, **kwargs)
  File "/home/ubuntu/cc-bench/apps/frappe/frappe/commands/scheduler.py", line 208, in start_worker
    start_worker(
  File "/home/ubuntu/cc-bench/apps/frappe/frappe/utils/background_jobs.py", line 249, in start_worker
    worker.work(
  File "/home/ubuntu/cc-bench/env/lib/python3.10/site-packages/rq/worker.py", line 645, in work
    self.unsubscribe()
  File "/home/ubuntu/cc-bench/env/lib/python3.10/site-packages/rq/worker.py", line 550, in unsubscribe
    self.pubsub.unsubscribe()
  File "/home/ubuntu/cc-bench/env/lib/python3.10/site-packages/redis/client.py", line 1648, in unsubscribe
    return self.execute_command("UNSUBSCRIBE", *args)
  File "/home/ubuntu/cc-bench/env/lib/python3.10/site-packages/redis/client.py", line 1468, in execute_command
    self._execute(connection, connection.send_command, *args, **kwargs)
  File "/home/ubuntu/cc-bench/env/lib/python3.10/site-packages/redis/client.py", line 1507, in _execute
    return conn.retry.call_with_retry(
  File "/home/ubuntu/cc-bench/env/lib/python3.10/site-packages/redis/retry.py", line 49, in call_with_retry
    fail(error)
  File "/home/ubuntu/cc-bench/env/lib/python3.10/site-packages/redis/client.py", line 1509, in <lambda>
    lambda error: self._disconnect_raise_connect(conn, error),
  File "/home/ubuntu/cc-bench/env/lib/python3.10/site-packages/redis/client.py", line 1496, in _disconnect_raise_connect
    raise error
  File "/home/ubuntu/cc-bench/env/lib/python3.10/site-packages/redis/retry.py", line 46, in call_with_retry
    return do()
  File "/home/ubuntu/cc-bench/env/lib/python3.10/site-packages/redis/client.py", line 1508, in <lambda>
    lambda: command(*args, **kwargs),
  File "/home/ubuntu/cc-bench/env/lib/python3.10/site-packages/redis/connection.py", line 840, in send_command
    self.send_packed_command(
  File "/home/ubuntu/cc-bench/env/lib/python3.10/site-packages/redis/connection.py", line 814, in send_packed_command
    self.connect()
  File "/home/ubuntu/cc-bench/env/lib/python3.10/site-packages/redis/connection.py", line 704, in connect
    raise ConnectionError(self._error_message(e))
redis.exceptions.ConnectionError: Error 111 connecting to localhost:11000. Connection refused.
Traceback (most recent call last):
  File "/home/ubuntu/cc-bench/env/lib/python3.10/site-packages/redis/connection.py", line 865, in read_response
    response = self._parser.read_response(disable_decoding=disable_decoding)
  File "/home/ubuntu/cc-bench/env/lib/python3.10/site-packages/redis/connection.py", line 492, in read_response
    self.read_from_socket()
  File "/home/ubuntu/cc-bench/env/lib/python3.10/site-packages/redis/connection.py", line 452, in read_from_socket
    bufflen = self._sock.recv_into(self._buffer)
ConnectionResetError: [Errno 104] Connection reset by peer

During handling of the above exception, another exception occurred:

Traceback (most recent call last):
  File "/usr/lib/python3.10/runpy.py", line 196, in _run_module_as_main
    return _run_code(code, main_globals, None,
  File "/usr/lib/python3.10/runpy.py", line 86, in _run_code
    exec(code, run_globals)
  File "/home/ubuntu/cc-bench/apps/frappe/frappe/utils/bench_helper.py", line 104, in <module>
    main()
  File "/home/ubuntu/cc-bench/apps/frappe/frappe/utils/bench_helper.py", line 19, in main
    click.Group(commands=commands)(prog_name="bench")
  File "/home/ubuntu/cc-bench/env/lib/python3.10/site-packages/click/core.py", line 1130, in __call__
    return self.main(*args, **kwargs)
  File "/home/ubuntu/cc-bench/env/lib/python3.10/site-packages/click/core.py", line 1055, in main
    rv = self.invoke(ctx)
  File "/home/ubuntu/cc-bench/env/lib/python3.10/site-packages/click/core.py", line 1657, in invoke
    Exception in thread Thread-1:
Traceback (most recent call last):
  File "/usr/lib/python3.10/threading.py", line 1016, in _bootstrap_inner
    self.run()
  File "/home/ubuntu/cc-bench/env/lib/python3.10/site-packages/redis/client.py", line 1788, in run
    pubsub.get_message(ignore_subscribe_messages=True, timeout=sleep_time)
  File "/home/ubuntu/cc-bench/env/lib/python3.10/site-packages/redis/client.py", line 1679, in get_message
    response = self.parse_response(block=(timeout is None), timeout=timeout)
  File "/home/ubuntu/cc-bench/env/lib/python3.10/site-packages/redis/client.py", line 1531, in parse_response
    response = self._execute(conn, try_read)
  File "/home/ubuntu/cc-bench/env/lib/python3.10/site-packages/redis/client.py", line 1507, in _execute
    return conn.retry.call_with_retry(
  File "/home/ubuntu/cc-bench/env/lib/python3.10/site-packages/redis/retry.py", line 49, in call_with_retry
    fail(error)
  File "/home/ubuntu/cc-bench/env/lib/python3.10/site-packages/redis/client.py", line 1509, in <lambda>
    lambda error: self._disconnect_raise_connect(conn, error),
  File "/home/ubuntu/cc-bench/env/lib/python3.10/site-packages/redis/client.py", line 1496, in _disconnect_raise_connect
    raise error
  File "/home/ubuntu/cc-bench/env/lib/python3.10/site-packages/redis/retry.py", line 46, in call_with_retry
    return do()
  File "/home/ubuntu/cc-bench/env/lib/python3.10/site-packages/redis/client.py", line 1508, in <lambda>
    lambda: command(*args, **kwargs),
  File "/home/ubuntu/cc-bench/env/lib/python3.10/site-packages/redis/client.py", line 1525, in try_read
    if not conn.can_read(timeout=timeout):
  File "/home/ubuntu/cc-bench/env/lib/python3.10/site-packages/redis/connection.py", line 854, in can_read
    return self._parser.can_read(timeout)
  File "/home/ubuntu/cc-bench/env/lib/python3.10/site-packages/redis/connection.py", line 443, in can_read
    return self.read_from_socket(timeout=timeout, raise_on_timeout=False)
  File "/home/ubuntu/cc-bench/env/lib/python3.10/site-packages/redis/connection.py", line 454, in read_from_socket
    raise ConnectionError(SERVER_CLOSED_CONNECTION_ERROR)
redis.exceptions.ConnectionError: Connection closed by server.
return _process_result(sub_ctx.command.invoke(sub_ctx))
  File "/home/ubuntu/cc-bench/env/lib/python3.10/site-packages/click/core.py", line 1657, in invoke
    return _process_result(sub_ctx.command.invoke(sub_ctx))
  File "/home/ubuntu/cc-bench/env/lib/python3.10/site-packages/click/core.py", line 1404, in invoke
    return ctx.invoke(self.callback, **ctx.params)
  File "/home/ubuntu/cc-bench/env/lib/python3.10/site-packages/click/core.py", line 760, in invoke
    return __callback(*args, **kwargs)
  File "/home/ubuntu/cc-bench/apps/frappe/frappe/commands/scheduler.py", line 208, in start_worker
    start_worker(
  File "/home/ubuntu/cc-bench/apps/frappe/frappe/utils/background_jobs.py", line 249, in start_worker
    worker.work(
  File "/home/ubuntu/cc-bench/env/lib/python3.10/site-packages/rq/worker.py", line 644, in work
    self.register_death()
  File "/home/ubuntu/cc-bench/env/lib/python3.10/site-packages/rq/worker.py", line 344, in register_death
    p.execute()
  File "/home/ubuntu/cc-bench/env/lib/python3.10/site-packages/redis/client.py", line 2109, in execute
    return conn.retry.call_with_retry(
  File "/home/ubuntu/cc-bench/env/lib/python3.10/site-packages/redis/retry.py", line 49, in call_with_retry
    fail(error)
  File "/home/ubuntu/cc-bench/env/lib/python3.10/site-packages/redis/client.py", line 2111, in <lambda>
    lambda error: self._disconnect_raise_reset(conn, error),
  File "/home/ubuntu/cc-bench/env/lib/python3.10/site-packages/redis/retry.py", line 46, in call_with_retry
    return do()
  File "/home/ubuntu/cc-bench/env/lib/python3.10/site-packages/redis/client.py", line 2110, in <lambda>
    lambda: execute(conn, stack, raise_on_error),
  File "/home/ubuntu/cc-bench/env/lib/python3.10/site-packages/redis/client.py", line 1964, in _execute_transaction
    self.parse_response(connection, "_")
  File "/home/ubuntu/cc-bench/env/lib/python3.10/site-packages/redis/client.py", line 2049, in parse_response
    result = Redis.parse_response(self, connection, command_name, **options)
  File "/home/ubuntu/cc-bench/env/lib/python3.10/site-packages/redis/client.py", line 1275, in parse_response
    response = connection.read_response()
  File "/home/ubuntu/cc-bench/env/lib/python3.10/site-packages/redis/connection.py", line 871, in read_response
    raise ConnectionError(
redis.exceptions.ConnectionError: Error while reading from localhost:11000 : (104, 'Connection reset by peer')
Exception in thread Thread-1:
Traceback (most recent call last):
  File "/usr/lib/python3.10/threading.py", line 1016, in _bootstrap_inner
    self.run()
  File "/home/ubuntu/cc-bench/env/lib/python3.10/site-packages/redis/client.py", line 1788, in run
    pubsub.get_message(ignore_subscribe_messages=True, timeout=sleep_time)
  File "/home/ubuntu/cc-bench/env/lib/python3.10/site-packages/redis/client.py", line 1679, in get_message
    response = self.parse_response(block=(timeout is None), timeout=timeout)
  File "/home/ubuntu/cc-bench/env/lib/python3.10/site-packages/redis/client.py", line 1531, in parse_response
    response = self._execute(conn, try_read)
  File "/home/ubuntu/cc-bench/env/lib/python3.10/site-packages/redis/client.py", line 1507, in _execute
    return conn.retry.call_with_retry(
  File "/home/ubuntu/cc-bench/env/lib/python3.10/site-packages/redis/retry.py", line 49, in call_with_retry
    fail(error)
  File "/home/ubuntu/cc-bench/env/lib/python3.10/site-packages/redis/client.py", line 1509, in <lambda>
    lambda error: self._disconnect_raise_connect(conn, error),
  File "/home/ubuntu/cc-bench/env/lib/python3.10/site-packages/redis/client.py", line 1496, in _disconnect_raise_connect
    raise error
  File "/home/ubuntu/cc-bench/env/lib/python3.10/site-packages/redis/retry.py", line 46, in call_with_retry
    return do()
  File "/home/ubuntu/cc-bench/env/lib/python3.10/site-packages/redis/client.py", line 1508, in <lambda>
    lambda: command(*args, **kwargs),
  File "/home/ubuntu/cc-bench/env/lib/python3.10/site-packages/redis/client.py", line 1525, in try_read
    if not conn.can_read(timeout=timeout):
  File "/home/ubuntu/cc-bench/env/lib/python3.10/site-packages/redis/connection.py", line 854, in can_read
    return self._parser.can_read(timeout)
  File "/home/ubuntu/cc-bench/env/lib/python3.10/site-packages/redis/connection.py", line 443, in can_read
    return self.read_from_socket(timeout=timeout, raise_on_timeout=False)
  File "/home/ubuntu/cc-bench/env/lib/python3.10/site-packages/redis/connection.py", line 454, in read_from_socket
    raise ConnectionError(SERVER_CLOSED_CONNECTION_ERROR)
redis.exceptions.ConnectionError: Connection closed by server.
Traceback (most recent call last):
  File "/home/ubuntu/cc-bench/env/lib/python3.10/site-packages/redis/connection.py", line 698, in connect
    sock = self.retry.call_with_retry(
  File "/home/ubuntu/cc-bench/env/lib/python3.10/site-packages/redis/retry.py", line 46, in call_with_retry
    return do()
  File "/home/ubuntu/cc-bench/env/lib/python3.10/site-packages/redis/connection.py", line 699, in <lambda>
    lambda: self._connect(), lambda error: self.disconnect(error)
  File "/home/ubuntu/cc-bench/env/lib/python3.10/site-packages/redis/connection.py", line 987, in _connect
    raise err
  File "/home/ubuntu/cc-bench/env/lib/python3.10/site-packages/redis/connection.py", line 975, in _connect
    sock.connect(socket_address)
ConnectionRefusedError: [Errno 111] Connection refused

During handling of the above exception, another exception occurred:

Traceback (most recent call last):
  File "/usr/lib/python3.10/runpy.py", line 196, in _run_module_as_main
    return _run_code(code, main_globals, None,
  File "/usr/lib/python3.10/runpy.py", line 86, in _run_code
    exec(code, run_globals)
  File "/home/ubuntu/cc-bench/apps/frappe/frappe/utils/bench_helper.py", line 104, in <module>
    main()
  File "/home/ubuntu/cc-bench/apps/frappe/frappe/utils/bench_helper.py", line 19, in main
    click.Group(commands=commands)(prog_name="bench")
  File "/home/ubuntu/cc-bench/env/lib/python3.10/site-packages/click/core.py", line 1130, in __call__
    return self.main(*args, **kwargs)
  File "/home/ubuntu/cc-bench/env/lib/python3.10/site-packages/click/core.py", line 1055, in main
    rv = self.invoke(ctx)
  File "/home/ubuntu/cc-bench/env/lib/python3.10/site-packages/click/core.py", line 1657, in invoke
    return _process_result(sub_ctx.command.invoke(sub_ctx))
  File "/home/ubuntu/cc-bench/env/lib/python3.10/site-packages/click/core.py", line 1657, in invoke
    return _process_result(sub_ctx.command.invoke(sub_ctx))
  File "/home/ubuntu/cc-bench/env/lib/python3.10/site-packages/click/core.py", line 1404, in invoke
    return ctx.invoke(self.callback, **ctx.params)
  File "/home/ubuntu/cc-bench/env/lib/python3.10/site-packages/click/core.py", line 760, in invoke
    return __callback(*args, **kwargs)
  File "/home/ubuntu/cc-bench/apps/frappe/frappe/commands/scheduler.py", line 208, in start_worker
    start_worker(
  File "/home/ubuntu/cc-bench/apps/frappe/frappe/utils/background_jobs.py", line 249, in start_worker
    worker.work(
  File "/home/ubuntu/cc-bench/env/lib/python3.10/site-packages/rq/worker.py", line 645, in work
    self.unsubscribe()
  File "/home/ubuntu/cc-bench/env/lib/python3.10/site-packages/rq/worker.py", line 550, in unsubscribe
    self.pubsub.unsubscribe()
  File "/home/ubuntu/cc-bench/env/lib/python3.10/site-packages/redis/client.py", line 1648, in unsubscribe
    return self.execute_command("UNSUBSCRIBE", *args)
  File "/home/ubuntu/cc-bench/env/lib/python3.10/site-packages/redis/client.py", line 1468, in execute_command
    self._execute(connection, connection.send_command, *args, **kwargs)
  File "/home/ubuntu/cc-bench/env/lib/python3.10/site-packages/redis/client.py", line 1507, in _execute
    return conn.retry.call_with_retry(
  File "/home/ubuntu/cc-bench/env/lib/python3.10/site-packages/redis/retry.py", line 49, in call_with_retry
    fail(error)
  File "/home/ubuntu/cc-bench/env/lib/python3.10/site-packages/redis/client.py", line 1509, in <lambda>
    lambda error: self._disconnect_raise_connect(conn, error),
  File "/home/ubuntu/cc-bench/env/lib/python3.10/site-packages/redis/client.py", line 1496, in _disconnect_raise_connect
    raise error
  File "/home/ubuntu/cc-bench/env/lib/python3.10/site-packages/redis/retry.py", line 46, in call_with_retry
    return do()
  File "/home/ubuntu/cc-bench/env/lib/python3.10/site-packages/redis/client.py", line 1508, in <lambda>
    lambda: command(*args, **kwargs),
  File "/home/ubuntu/cc-bench/env/lib/python3.10/site-packages/redis/connection.py", line 840, in send_command
    self.send_packed_command(
  File "/home/ubuntu/cc-bench/env/lib/python3.10/site-packages/redis/connection.py", line 814, in send_packed_command
    self.connect()
  File "/home/ubuntu/cc-bench/env/lib/python3.10/site-packages/redis/connection.py", line 704, in connect
    raise ConnectionError(self._error_message(e))
redis.exceptions.ConnectionError: Error 111 connecting to localhost:11000. Connection refused.
/home/ubuntu/cc-bench/apps/frappe/frappe/utils/pdf.py:7: DeprecationWarning: The distutils package is deprecated and slated for removal in Python 3.12. Use setuptools or check PEP 632 for potential alternatives
  from distutils.version import LooseVersion
/home/ubuntu/cc-bench/apps/frappe/frappe/utils/pdf.py:7: DeprecationWarning: The distutils package is deprecated and slated for removal in Python 3.12. Use setuptools or check PEP 632 for potential alternatives
  from distutils.version import LooseVersion
/home/ubuntu/cc-bench/apps/frappe/frappe/utils/pdf.py:7: DeprecationWarning: The distutils package is deprecated and slated for removal in Python 3.12. Use setuptools or check PEP 632 for potential alternatives
  from distutils.version import LooseVersion
Exception in thread Thread-1:
Traceback (most recent call last):
  File "/usr/lib/python3.10/threading.py", line 1016, in _bootstrap_inner
    self.run()
  File "/home/ubuntu/cc-bench/env/lib/python3.10/site-packages/redis/client.py", line 1788, in run
    pubsub.get_message(ignore_subscribe_messages=True, timeout=sleep_time)
  File "/home/ubuntu/cc-bench/env/lib/python3.10/site-packages/redis/client.py", line 1679, in get_message
    response = self.parse_response(block=(timeout is None), timeout=timeout)
  File "/home/ubuntu/cc-bench/env/lib/python3.10/site-packages/redis/client.py", line 1531, in parse_response
    response = self._execute(conn, try_read)
  File "/home/ubuntu/cc-bench/env/lib/python3.10/site-packages/redis/client.py", line 1507, in _execute
    return conn.retry.call_with_retry(
  File "/home/ubuntu/cc-bench/env/lib/python3.10/site-packages/redis/retry.py", line 49, in call_with_retry
    fail(error)
  File "/home/ubuntu/cc-bench/env/lib/python3.10/site-packages/redis/client.py", line 1509, in <lambda>
    lambda error: self._disconnect_raise_connect(conn, error),
  File "/home/ubuntu/cc-bench/env/lib/python3.10/site-packages/redis/client.py", line 1496, in _disconnect_raise_connect
    raise error
  File "/home/ubuntu/cc-bench/env/lib/python3.10/site-packages/redis/retry.py", line 46, in call_with_retry
    return do()
  File "/home/ubuntu/cc-bench/env/lib/python3.10/site-packages/redis/client.py", line 1508, in <lambda>
    lambda: command(*args, **kwargs),
  File "/home/ubuntu/cc-bench/env/lib/python3.10/site-packages/redis/client.py", line 1525, in try_read
    if not conn.can_read(timeout=timeout):
  File "/home/ubuntu/cc-bench/env/lib/python3.10/site-packages/redis/connection.py", line 854, in can_read
    return self._parser.can_read(timeout)
  File "/home/ubuntu/cc-bench/env/lib/python3.10/site-packages/redis/connection.py", line 443, in can_read
    return self.read_from_socket(timeout=timeout, raise_on_timeout=False)
  File "/home/ubuntu/cc-bench/env/lib/python3.10/site-packages/redis/connection.py", line 454, in read_from_socket
    raise ConnectionError(SERVER_CLOSED_CONNECTION_ERROR)
redis.exceptions.ConnectionError: Connection closed by server.
2023-05-05 15:28:32,160 Worker rq:worker:b8fef00c806e4afaaf54cbbb22f4675e: found an unhandled exception, quitting...
Traceback (most recent call last):
  File "/home/ubuntu/cc-bench/env/lib/python3.10/site-packages/redis/connection.py", line 865, in read_response
    response = self._parser.read_response(disable_decoding=disable_decoding)
  File "/home/ubuntu/cc-bench/env/lib/python3.10/site-packages/redis/connection.py", line 492, in read_response
    self.read_from_socket()
  File "/home/ubuntu/cc-bench/env/lib/python3.10/site-packages/redis/connection.py", line 452, in read_from_socket
    bufflen = self._sock.recv_into(self._buffer)
ConnectionResetError: [Errno 104] Connection reset by peer

During handling of the above exception, another exception occurred:

Traceback (most recent call last):
  File "/home/ubuntu/cc-bench/env/lib/python3.10/site-packages/rq/worker.py", line 613, in work
    self.execute_job(job, queue)
  File "/home/ubuntu/cc-bench/env/lib/python3.10/site-packages/rq/worker.py", line 874, in execute_job
    self.monitor_work_horse(job, queue)
  File "/home/ubuntu/cc-bench/env/lib/python3.10/site-packages/rq/worker.py", line 806, in monitor_work_horse
    retpid, ret_val = self.wait_for_horse()
  File "/home/ubuntu/cc-bench/env/lib/python3.10/site-packages/rq/worker.py", line 451, in wait_for_horse
    pid, stat = os.waitpid(self.horse_pid, 0)
  File "/home/ubuntu/cc-bench/env/lib/python3.10/site-packages/rq/worker.py", line 479, in request_stop
    self._shutdown()
  File "/home/ubuntu/cc-bench/env/lib/python3.10/site-packages/rq/worker.py", line 488, in _shutdown
    self.set_shutdown_requested_date()
  File "/home/ubuntu/cc-bench/env/lib/python3.10/site-packages/rq/worker.py", line 348, in set_shutdown_requested_date
    self.connection.hset(self.key, 'shutdown_requested_date', utcformat(utcnow()))
  File "/home/ubuntu/cc-bench/env/lib/python3.10/site-packages/redis/commands/core.py", line 4932, in hset
    return self.execute_command("HSET", name, *items)
  File "/home/ubuntu/cc-bench/env/lib/python3.10/site-packages/redis/client.py", line 1258, in execute_command
    return conn.retry.call_with_retry(
  File "/home/ubuntu/cc-bench/env/lib/python3.10/site-packages/redis/retry.py", line 49, in call_with_retry
    fail(error)
  File "/home/ubuntu/cc-bench/env/lib/python3.10/site-packages/redis/client.py", line 1262, in <lambda>
    lambda error: self._disconnect_raise(conn, error),
  File "/home/ubuntu/cc-bench/env/lib/python3.10/site-packages/redis/client.py", line 1248, in _disconnect_raise
    raise error
  File "/home/ubuntu/cc-bench/env/lib/python3.10/site-packages/redis/retry.py", line 46, in call_with_retry
    return do()
  File "/home/ubuntu/cc-bench/env/lib/python3.10/site-packages/redis/client.py", line 1259, in <lambda>
    lambda: self._send_command_parse_response(
  File "/home/ubuntu/cc-bench/env/lib/python3.10/site-packages/redis/client.py", line 1235, in _send_command_parse_response
    return self.parse_response(conn, command_name, **options)
  File "/home/ubuntu/cc-bench/env/lib/python3.10/site-packages/redis/client.py", line 1275, in parse_response
    response = connection.read_response()
  File "/home/ubuntu/cc-bench/env/lib/python3.10/site-packages/redis/connection.py", line 871, in read_response
    raise ConnectionError(
redis.exceptions.ConnectionError: Error while reading from localhost:11000 : (104, 'Connection reset by peer')
Traceback (most recent call last):
  File "/home/ubuntu/cc-bench/env/lib/python3.10/site-packages/redis/connection.py", line 698, in connect
    sock = self.retry.call_with_retry(
  File "/home/ubuntu/cc-bench/env/lib/python3.10/site-packages/redis/retry.py", line 46, in call_with_retry
    return do()
  File "/home/ubuntu/cc-bench/env/lib/python3.10/site-packages/redis/connection.py", line 699, in <lambda>
    lambda: self._connect(), lambda error: self.disconnect(error)
  File "/home/ubuntu/cc-bench/env/lib/python3.10/site-packages/redis/connection.py", line 987, in _connect
    raise err
  File "/home/ubuntu/cc-bench/env/lib/python3.10/site-packages/redis/connection.py", line 975, in _connect
    sock.connect(socket_address)
ConnectionRefusedError: [Errno 111] Connection refused

During handling of the above exception, another exception occurred:

Traceback (most recent call last):
  File "/usr/lib/python3.10/runpy.py", line 196, in _run_module_as_main
    return _run_code(code, main_globals, None,
  File "/usr/lib/python3.10/runpy.py", line 86, in _run_code
    exec(code, run_globals)
  File "/home/ubuntu/cc-bench/apps/frappe/frappe/utils/bench_helper.py", line 104, in <module>
    main()
  File "/home/ubuntu/cc-bench/apps/frappe/frappe/utils/bench_helper.py", line 19, in main
    click.Group(commands=commands)(prog_name="bench")
  File "/home/ubuntu/cc-bench/env/lib/python3.10/site-packages/click/core.py", line 1130, in __call__
    return self.main(*args, **kwargs)
  File "/home/ubuntu/cc-bench/env/lib/python3.10/site-packages/click/core.py", line 1055, in main
    rv = self.invoke(ctx)
  File "/home/ubuntu/cc-bench/env/lib/python3.10/site-packages/click/core.py", line 1657, in invoke
    return _process_result(sub_ctx.command.invoke(sub_ctx))
  File "/home/ubuntu/cc-bench/env/lib/python3.10/site-packages/click/core.py", line 1657, in invoke
    return _process_result(sub_ctx.command.invoke(sub_ctx))
  File "/home/ubuntu/cc-bench/env/lib/python3.10/site-packages/click/core.py", line 1404, in invoke
    return ctx.invoke(self.callback, **ctx.params)
  File "/home/ubuntu/cc-bench/env/lib/python3.10/site-packages/click/core.py", line 760, in invoke
    return __callback(*args, **kwargs)
  File "/home/ubuntu/cc-bench/apps/frappe/frappe/commands/scheduler.py", line 208, in start_worker
    start_worker(
  File "/home/ubuntu/cc-bench/apps/frappe/frappe/utils/background_jobs.py", line 249, in start_worker
    worker.work(
  File "/home/ubuntu/cc-bench/env/lib/python3.10/site-packages/rq/worker.py", line 644, in work
    self.register_death()
  File "/home/ubuntu/cc-bench/env/lib/python3.10/site-packages/rq/worker.py", line 344, in register_death
    p.execute()
  File "/home/ubuntu/cc-bench/env/lib/python3.10/site-packages/redis/client.py", line 2103, in execute
    conn = self.connection_pool.get_connection("MULTI", self.shard_hint)
  File "/home/ubuntu/cc-bench/env/lib/python3.10/site-packages/redis/connection.py", line 1442, in get_connection
    connection.connect()
  File "/home/ubuntu/cc-bench/env/lib/python3.10/site-packages/redis/connection.py", line 704, in connect
    raise ConnectionError(self._error_message(e))
redis.exceptions.ConnectionError: Error 111 connecting to localhost:11000. Connection refused.
2023-05-05 15:28:32,507 Traceback (most recent call last):
  File "/home/ubuntu/cc-bench/env/lib/python3.10/site-packages/redis/connection.py", line 1448, in get_connection
    if connection.can_read():
  File "/home/ubuntu/cc-bench/env/lib/python3.10/site-packages/redis/connection.py", line 854, in can_read
    return self._parser.can_read(timeout)
  File "/home/ubuntu/cc-bench/env/lib/python3.10/site-packages/redis/connection.py", line 443, in can_read
    return self.read_from_socket(timeout=timeout, raise_on_timeout=False)
  File "/home/ubuntu/cc-bench/env/lib/python3.10/site-packages/redis/connection.py", line 454, in read_from_socket
    raise ConnectionError(SERVER_CLOSED_CONNECTION_ERROR)
redis.exceptions.ConnectionError: Connection closed by server.

During handling of the above exception, another exception occurred:

Traceback (most recent call last):
  File "/home/ubuntu/cc-bench/env/lib/python3.10/site-packages/redis/connection.py", line 698, in connect
    sock = self.retry.call_with_retry(
  File "/home/ubuntu/cc-bench/env/lib/python3.10/site-packages/redis/retry.py", line 46, in call_with_retry
    return do()
  File "/home/ubuntu/cc-bench/env/lib/python3.10/site-packages/redis/connection.py", line 699, in <lambda>
    lambda: self._connect(), lambda error: self.disconnect(error)
  File "/home/ubuntu/cc-bench/env/lib/python3.10/site-packages/redis/connection.py", line 987, in _connect
    raise err
  File "/home/ubuntu/cc-bench/env/lib/python3.10/site-packages/redis/connection.py", line 975, in _connect
    sock.connect(socket_address)
ConnectionRefusedError: [Errno 111] Connection refused

During handling of the above exception, another exception occurred:

Traceback (most recent call last):
  File "/home/ubuntu/cc-bench/env/lib/python3.10/site-packages/rq/worker.py", line 1086, in perform_job
    self.handle_job_success(job=job,
  File "/home/ubuntu/cc-bench/env/lib/python3.10/site-packages/rq/worker.py", line 1017, in handle_job_success
    pipeline.watch(job.dependents_key)
  File "/home/ubuntu/cc-bench/env/lib/python3.10/site-packages/redis/client.py", line 2127, in watch
    return self.execute_command("WATCH", *names)
  File "/home/ubuntu/cc-bench/env/lib/python3.10/site-packages/redis/client.py", line 1890, in execute_command
    return self.immediate_execute_command(*args, **kwargs)
  File "/home/ubuntu/cc-bench/env/lib/python3.10/site-packages/redis/client.py", line 1926, in immediate_execute_command
    conn = self.connection_pool.get_connection(command_name, self.shard_hint)
  File "/home/ubuntu/cc-bench/env/lib/python3.10/site-packages/redis/connection.py", line 1452, in get_connection
    connection.connect()
  File "/home/ubuntu/cc-bench/env/lib/python3.10/site-packages/redis/connection.py", line 704, in connect
    raise ConnectionError(self._error_message(e))
redis.exceptions.ConnectionError: Error 111 connecting to localhost:11000. Connection refused.
Traceback (most recent call last):
  File "/home/ubuntu/cc-bench/env/lib/python3.10/site-packages/redis/connection.py", line 1448, in get_connection
    if connection.can_read():
  File "/home/ubuntu/cc-bench/env/lib/python3.10/site-packages/redis/connection.py", line 854, in can_read
    return self._parser.can_read(timeout)
  File "/home/ubuntu/cc-bench/env/lib/python3.10/site-packages/redis/connection.py", line 443, in can_read
    return self.read_from_socket(timeout=timeout, raise_on_timeout=False)
  File "/home/ubuntu/cc-bench/env/lib/python3.10/site-packages/redis/connection.py", line 454, in read_from_socket
    raise ConnectionError(SERVER_CLOSED_CONNECTION_ERROR)
redis.exceptions.ConnectionError: Connection closed by server.

During handling of the above exception, another exception occurred:

Traceback (most recent call last):
  File "/home/ubuntu/cc-bench/env/lib/python3.10/site-packages/redis/connection.py", line 698, in connect
    sock = self.retry.call_with_retry(
  File "/home/ubuntu/cc-bench/env/lib/python3.10/site-packages/redis/retry.py", line 46, in call_with_retry
    return do()
  File "/home/ubuntu/cc-bench/env/lib/python3.10/site-packages/redis/connection.py", line 699, in <lambda>
    lambda: self._connect(), lambda error: self.disconnect(error)
  File "/home/ubuntu/cc-bench/env/lib/python3.10/site-packages/redis/connection.py", line 987, in _connect
    raise err
  File "/home/ubuntu/cc-bench/env/lib/python3.10/site-packages/redis/connection.py", line 975, in _connect
    sock.connect(socket_address)
ConnectionRefusedError: [Errno 111] Connection refused

During handling of the above exception, another exception occurred:

Traceback (most recent call last):
  File "/home/ubuntu/cc-bench/env/lib/python3.10/site-packages/rq/worker.py", line 1086, in perform_job
    self.handle_job_success(job=job,
  File "/home/ubuntu/cc-bench/env/lib/python3.10/site-packages/rq/worker.py", line 1017, in handle_job_success
    pipeline.watch(job.dependents_key)
  File "/home/ubuntu/cc-bench/env/lib/python3.10/site-packages/redis/client.py", line 2127, in watch
    return self.execute_command("WATCH", *names)
  File "/home/ubuntu/cc-bench/env/lib/python3.10/site-packages/redis/client.py", line 1890, in execute_command
    return self.immediate_execute_command(*args, **kwargs)
  File "/home/ubuntu/cc-bench/env/lib/python3.10/site-packages/redis/client.py", line 1926, in immediate_execute_command
    conn = self.connection_pool.get_connection(command_name, self.shard_hint)
  File "/home/ubuntu/cc-bench/env/lib/python3.10/site-packages/redis/connection.py", line 1452, in get_connection
    connection.connect()
  File "/home/ubuntu/cc-bench/env/lib/python3.10/site-packages/redis/connection.py", line 704, in connect
    raise ConnectionError(self._error_message(e))
redis.exceptions.ConnectionError: Error 111 connecting to localhost:11000. Connection refused.
/home/ubuntu/cc-bench/apps/frappe/frappe/utils/pdf.py:7: DeprecationWarning: The distutils package is deprecated and slated for removal in Python 3.12. Use setuptools or check PEP 632 for potential alternatives
  from distutils.version import LooseVersion
/home/ubuntu/cc-bench/apps/frappe/frappe/utils/pdf.py:7: DeprecationWarning: The distutils package is deprecated and slated for removal in Python 3.12. Use setuptools or check PEP 632 for potential alternatives
  from distutils.version import LooseVersion
/home/ubuntu/cc-bench/env/lib/python3.10/site-packages/botocore/httpsession.py:19: DeprecationWarning: 'urllib3.contrib.pyopenssl' module is deprecated and will be removed in a future release of urllib3 2.x. Read more in this issue: https://github.com/urllib3/urllib3/issues/2680
  from urllib3.contrib.pyopenssl import orig_util_SSLContext as SSLContext
/home/ubuntu/cc-bench/env/lib/python3.10/site-packages/botocore/httpsession.py:19: DeprecationWarning: 'urllib3.contrib.pyopenssl' module is deprecated and will be removed in a future release of urllib3 2.x. Read more in this issue: https://github.com/urllib3/urllib3/issues/2680
  from urllib3.contrib.pyopenssl import orig_util_SSLContext as SSLContext
/home/ubuntu/cc-bench/env/lib/python3.10/site-packages/botocore/httpsession.py:19: DeprecationWarning: 'urllib3.contrib.pyopenssl' module is deprecated and will be removed in a future release of urllib3 2.x. Read more in this issue: https://github.com/urllib3/urllib3/issues/2680
  from urllib3.contrib.pyopenssl import orig_util_SSLContext as SSLContext
/home/ubuntu/cc-bench/apps/frappe/frappe/utils/pdf.py:7: DeprecationWarning: The distutils package is deprecated and slated for removal in Python 3.12. Use setuptools or check PEP 632 for potential alternatives
  from distutils.version import LooseVersion
/home/ubuntu/cc-bench/apps/frappe/frappe/utils/pdf.py:7: DeprecationWarning: The distutils package is deprecated and slated for removal in Python 3.12. Use setuptools or check PEP 632 for potential alternatives
  from distutils.version import LooseVersion
/home/ubuntu/cc-bench/apps/frappe/frappe/utils/pdf.py:7: DeprecationWarning: The distutils package is deprecated and slated for removal in Python 3.12. Use setuptools or check PEP 632 for potential alternatives
  from distutils.version import LooseVersion
Exception in thread Thread-1:
Traceback (most recent call last):
  File "/usr/lib/python3.10/threading.py", line 1016, in _bootstrap_inner
    self.run()
  File "/home/ubuntu/cc-bench/env/lib/python3.10/site-packages/redis/client.py", line 1788, in run
    pubsub.get_message(ignore_subscribe_messages=True, timeout=sleep_time)
  File "/home/ubuntu/cc-bench/env/lib/python3.10/site-packages/redis/client.py", line 1679, in get_message
    response = self.parse_response(block=(timeout is None), timeout=timeout)
  File "/home/ubuntu/cc-bench/env/lib/python3.10/site-packages/redis/client.py", line 1531, in parse_response
    response = self._execute(conn, try_read)
  File "/home/ubuntu/cc-bench/env/lib/python3.10/site-packages/redis/client.py", line 1507, in _execute
    return conn.retry.call_with_retry(
  File "/home/ubuntu/cc-bench/env/lib/python3.10/site-packages/redis/retry.py", line 49, in call_with_retry
    fail(error)
  File "/home/ubuntu/cc-bench/env/lib/python3.10/site-packages/redis/client.py", line 1509, in <lambda>
    lambda error: self._disconnect_raise_connect(conn, error),
  File "/home/ubuntu/cc-bench/env/lib/python3.10/site-packages/redis/client.py", line 1496, in _disconnect_raise_connect
    raise error
  File "/home/ubuntu/cc-bench/env/lib/python3.10/site-packages/redis/retry.py", line 46, in call_with_retry
    return do()
  File "/home/ubuntu/cc-bench/env/lib/python3.10/site-packages/redis/client.py", line 1508, in <lambda>
    lambda: command(*args, **kwargs),
  File "/home/ubuntu/cc-bench/env/lib/python3.10/site-packages/redis/client.py", line 1525, in try_read
    if not conn.can_read(timeout=timeout):
  File "/home/ubuntu/cc-bench/env/lib/python3.10/site-packages/redis/connection.py", line 854, in can_read
    return self._parser.can_read(timeout)
  File "/home/ubuntu/cc-bench/env/lib/python3.10/site-packages/redis/connection.py", line 443, in can_read
    return self.read_from_socket(timeout=timeout, raise_on_timeout=False)
  File "/home/ubuntu/cc-bench/env/lib/python3.10/site-packages/redis/connection.py", line 454, in read_from_socket
    raise ConnectionError(SERVER_CLOSED_CONNECTION_ERROR)
redis.exceptions.ConnectionError: Connection closed by server.
Traceback (most recent call last):
  File "/home/ubuntu/cc-bench/env/lib/python3.10/site-packages/redis/connection.py", line 698, in connect
    sock = self.retry.call_with_retry(
  File "/home/ubuntu/cc-bench/env/lib/python3.10/site-packages/redis/retry.py", line 46, in call_with_retry
    return do()
  File "/home/ubuntu/cc-bench/env/lib/python3.10/site-packages/redis/connection.py", line 699, in <lambda>
    lambda: self._connect(), lambda error: self.disconnect(error)
  File "/home/ubuntu/cc-bench/env/lib/python3.10/site-packages/redis/connection.py", line 987, in _connect
    raise err
  File "/home/ubuntu/cc-bench/env/lib/python3.10/site-packages/redis/connection.py", line 975, in _connect
    sock.connect(socket_address)
ConnectionRefusedError: [Errno 111] Connection refused

During handling of the above exception, another exception occurred:

Traceback (most recent call last):
  File "/usr/lib/python3.10/runpy.py", line 196, in _run_module_as_main
    return _run_code(code, main_globals, None,
  File "/usr/lib/python3.10/runpy.py", line 86, in _run_code
    exec(code, run_globals)
  File "/home/ubuntu/cc-bench/apps/frappe/frappe/utils/bench_helper.py", line 104, in <module>
    main()
  File "/home/ubuntu/cc-bench/apps/frappe/frappe/utils/bench_helper.py", line 19, in main
    click.Group(commands=commands)(prog_name="bench")
  File "/home/ubuntu/cc-bench/env/lib/python3.10/site-packages/click/core.py", line 1130, in __call__
    return self.main(*args, **kwargs)
  File "/home/ubuntu/cc-bench/env/lib/python3.10/site-packages/click/core.py", line 1055, in main
    rv = self.invoke(ctx)
  File "/home/ubuntu/cc-bench/env/lib/python3.10/site-packages/click/core.py", line 1657, in invoke
    return _process_result(sub_ctx.command.invoke(sub_ctx))
  File "/home/ubuntu/cc-bench/env/lib/python3.10/site-packages/click/core.py", line 1657, in invoke
    return _process_result(sub_ctx.command.invoke(sub_ctx))
  File "/home/ubuntu/cc-bench/env/lib/python3.10/site-packages/click/core.py", line 1404, in invoke
    return ctx.invoke(self.callback, **ctx.params)
  File "/home/ubuntu/cc-bench/env/lib/python3.10/site-packages/click/core.py", line 760, in invoke
    return __callback(*args, **kwargs)
  File "/home/ubuntu/cc-bench/apps/frappe/frappe/commands/scheduler.py", line 208, in start_worker
    start_worker(
  File "/home/ubuntu/cc-bench/apps/frappe/frappe/utils/background_jobs.py", line 249, in start_worker
    worker.work(
  File "/home/ubuntu/cc-bench/env/lib/python3.10/site-packages/rq/worker.py", line 645, in work
    self.unsubscribe()
  File "/home/ubuntu/cc-bench/env/lib/python3.10/site-packages/rq/worker.py", line 550, in unsubscribe
    self.pubsub.unsubscribe()
  File "/home/ubuntu/cc-bench/env/lib/python3.10/site-packages/redis/client.py", line 1648, in unsubscribe
    return self.execute_command("UNSUBSCRIBE", *args)
  File "/home/ubuntu/cc-bench/env/lib/python3.10/site-packages/redis/client.py", line 1468, in execute_command
    self._execute(connection, connection.send_command, *args, **kwargs)
  File "/home/ubuntu/cc-bench/env/lib/python3.10/site-packages/redis/client.py", line 1507, in _execute
    return conn.retry.call_with_retry(
  File "/home/ubuntu/cc-bench/env/lib/python3.10/site-packages/redis/retry.py", line 49, in call_with_retry
    fail(error)
  File "/home/ubuntu/cc-bench/env/lib/python3.10/site-packages/redis/client.py", line 1509, in <lambda>
    lambda error: self._disconnect_raise_connect(conn, error),
  File "/home/ubuntu/cc-bench/env/lib/python3.10/site-packages/redis/client.py", line 1496, in _disconnect_raise_connect
    raise error
  File "/home/ubuntu/cc-bench/env/lib/python3.10/site-packages/redis/retry.py", line 46, in call_with_retry
    return do()
  File "/home/ubuntu/cc-bench/env/lib/python3.10/site-packages/redis/client.py", line 1508, in <lambda>
    lambda: command(*args, **kwargs),
  File "/home/ubuntu/cc-bench/env/lib/python3.10/site-packages/redis/connection.py", line 840, in send_command
    self.send_packed_command(
  File "/home/ubuntu/cc-bench/env/lib/python3.10/site-packages/redis/connection.py", line 814, in send_packed_command
    self.connect()
  File "/home/ubuntu/cc-bench/env/lib/python3.10/site-packages/redis/connection.py", line 704, in connect
    raise ConnectionError(self._error_message(e))
redis.exceptions.ConnectionError: Error 111 connecting to localhost:11000. Connection refused.
